[2024-06-22T12:01:46.151+0000] {taskinstance.py:1979} INFO - Dependencies all met for dep_context=non-requeueable deps ti=<TaskInstance: DAG_ml_pipeline_class_reg.run_modeling_regression manual__2024-06-22T12:01:38.111824+00:00 [queued]>
[2024-06-22T12:01:46.162+0000] {taskinstance.py:1979} INFO - Dependencies all met for dep_context=requeueable deps ti=<TaskInstance: DAG_ml_pipeline_class_reg.run_modeling_regression manual__2024-06-22T12:01:38.111824+00:00 [queued]>
[2024-06-22T12:01:46.163+0000] {taskinstance.py:2193} INFO - Starting attempt 1 of 1
[2024-06-22T12:01:46.181+0000] {taskinstance.py:2217} INFO - Executing <Task(PythonOperator): run_modeling_regression> on 2024-06-22 12:01:38.111824+00:00
[2024-06-22T12:01:46.187+0000] {standard_task_runner.py:60} INFO - Started process 2149 to run task
[2024-06-22T12:01:46.190+0000] {standard_task_runner.py:87} INFO - Running: ['***', 'tasks', 'run', 'DAG_ml_pipeline_class_reg', 'run_modeling_regression', 'manual__2024-06-22T12:01:38.111824+00:00', '--job-id', '18', '--raw', '--subdir', 'DAGS_FOLDER/run_data_wrangling_class_reg.py', '--cfg-path', '/tmp/tmpzdlvliuo']
[2024-06-22T12:01:46.193+0000] {standard_task_runner.py:88} INFO - Job 18: Subtask run_modeling_regression
[2024-06-22T12:01:46.247+0000] {task_command.py:423} INFO - Running <TaskInstance: DAG_ml_pipeline_class_reg.run_modeling_regression manual__2024-06-22T12:01:38.111824+00:00 [running]> on host 0fdcf3d7bc80
[2024-06-22T12:01:46.320+0000] {taskinstance.py:2513} INFO - Exporting env vars: AIRFLOW_CTX_DAG_OWNER='***' AIRFLOW_CTX_DAG_ID='DAG_ml_pipeline_class_reg' AIRFLOW_CTX_TASK_ID='run_modeling_regression' AIRFLOW_CTX_EXECUTION_DATE='2024-06-22T12:01:38.111824+00:00' AIRFLOW_CTX_TRY_NUMBER='1' AIRFLOW_CTX_DAG_RUN_ID='manual__2024-06-22T12:01:38.111824+00:00'
[2024-06-22T12:01:46.322+0000] {logging_mixin.py:188} INFO - Looking for .env file at: /opt/***/../../.env
[2024-06-22T12:01:46.323+0000] {logging_mixin.py:188} INFO - .env file does not exist at: /opt/***/../../.env
[2024-06-22T12:01:46.338+0000] {credentials.py:1278} INFO - Found credentials in shared credentials file: ~/.aws/credentials
[2024-06-22T12:01:46.415+0000] {taskinstance.py:2731} ERROR - Task failed with exception
Traceback (most recent call last):
  File "/home/airflow/.local/lib/python3.8/site-packages/airflow/models/taskinstance.py", line 444, in _execute_task
    result = _execute_callable(context=context, **execute_callable_kwargs)
  File "/home/airflow/.local/lib/python3.8/site-packages/airflow/models/taskinstance.py", line 414, in _execute_callable
    return execute_callable(context=context, **execute_callable_kwargs)
  File "/home/airflow/.local/lib/python3.8/site-packages/airflow/operators/python.py", line 200, in execute
    return_value = self.execute_callable()
  File "/home/airflow/.local/lib/python3.8/site-packages/airflow/operators/python.py", line 217, in execute_callable
    return self.python_callable(*self.op_args, **self.op_kwargs)
  File "/opt/airflow/dags/modeling_reg_tasks/modeling_reg.py", line 50, in main_modeling_reg
    obj = s3.get_object(Bucket=bucket_name, Key=f'{prefix}/ship_cost_classification/Data_Pred_Demurrage_True_Join.csv')
  File "/home/airflow/.local/lib/python3.8/site-packages/botocore/client.py", line 565, in _api_call
    return self._make_api_call(operation_name, kwargs)
  File "/home/airflow/.local/lib/python3.8/site-packages/botocore/client.py", line 958, in _make_api_call
    api_params = self._emit_api_params(
  File "/home/airflow/.local/lib/python3.8/site-packages/botocore/client.py", line 1084, in _emit_api_params
    self.meta.events.emit(
  File "/home/airflow/.local/lib/python3.8/site-packages/botocore/hooks.py", line 412, in emit
    return self._emitter.emit(aliased_event_name, **kwargs)
  File "/home/airflow/.local/lib/python3.8/site-packages/botocore/hooks.py", line 256, in emit
    return self._emit(event_name, kwargs)
  File "/home/airflow/.local/lib/python3.8/site-packages/botocore/hooks.py", line 239, in _emit
    response = handler(**kwargs)
  File "/home/airflow/.local/lib/python3.8/site-packages/botocore/handlers.py", line 282, in validate_bucket_name
    if not VALID_BUCKET.search(bucket) and not VALID_S3_ARN.search(bucket):
TypeError: expected string or bytes-like object
[2024-06-22T12:01:46.432+0000] {taskinstance.py:1149} INFO - Marking task as FAILED. dag_id=DAG_ml_pipeline_class_reg, task_id=run_modeling_regression, execution_date=20240622T120138, start_date=20240622T120146, end_date=20240622T120146
[2024-06-22T12:01:46.447+0000] {standard_task_runner.py:107} ERROR - Failed to execute job 18 for task run_modeling_regression (expected string or bytes-like object; 2149)
[2024-06-22T12:01:46.485+0000] {local_task_job_runner.py:234} INFO - Task exited with return code 1
[2024-06-22T12:01:46.502+0000] {taskinstance.py:3312} INFO - 0 downstream tasks scheduled from follow-on schedule check
